2024-07-17 16:35:06,135 ERROR: Exception on /products [GET] [in /home/dextermnesh/.local/share/virtualenvs/backend-GvKYjNis/lib/python3.10/site-packages/flask/app.py:838]
Traceback (most recent call last):
  File "/home/dextermnesh/.local/share/virtualenvs/backend-GvKYjNis/lib/python3.10/site-packages/sqlalchemy/engine/base.py", line 1967, in _exec_single_context
    self.dialect.do_execute(
  File "/home/dextermnesh/.local/share/virtualenvs/backend-GvKYjNis/lib/python3.10/site-packages/sqlalchemy/engine/default.py", line 924, in do_execute
    cursor.execute(statement, parameters)
psycopg2.errors.UndefinedTable: relation "products" does not exist
LINE 2: FROM products
             ^


The above exception was the direct cause of the following exception:

Traceback (most recent call last):
  File "/home/dextermnesh/.local/share/virtualenvs/backend-GvKYjNis/lib/python3.10/site-packages/flask/app.py", line 1473, in wsgi_app
    response = self.full_dispatch_request()
  File "/home/dextermnesh/.local/share/virtualenvs/backend-GvKYjNis/lib/python3.10/site-packages/flask/app.py", line 882, in full_dispatch_request
    rv = self.handle_user_exception(e)
  File "/home/dextermnesh/.local/share/virtualenvs/backend-GvKYjNis/lib/python3.10/site-packages/flask_cors/extension.py", line 178, in wrapped_function
    return cors_after_request(app.make_response(f(*args, **kwargs)))
  File "/home/dextermnesh/.local/share/virtualenvs/backend-GvKYjNis/lib/python3.10/site-packages/flask/app.py", line 880, in full_dispatch_request
    rv = self.dispatch_request()
  File "/home/dextermnesh/.local/share/virtualenvs/backend-GvKYjNis/lib/python3.10/site-packages/flask/app.py", line 865, in dispatch_request
    return self.ensure_sync(self.view_functions[rule.endpoint])(**view_args)  # type: ignore[no-any-return]
  File "/home/dextermnesh/Documents/testers/shopping-mall/backend/app.py", line 35, in get_products
    products = Product.query.all()
  File "/home/dextermnesh/.local/share/virtualenvs/backend-GvKYjNis/lib/python3.10/site-packages/sqlalchemy/orm/query.py", line 2673, in all
    return self._iter().all()  # type: ignore
  File "/home/dextermnesh/.local/share/virtualenvs/backend-GvKYjNis/lib/python3.10/site-packages/sqlalchemy/orm/query.py", line 2827, in _iter
    result: Union[ScalarResult[_T], Result[_T]] = self.session.execute(
  File "/home/dextermnesh/.local/share/virtualenvs/backend-GvKYjNis/lib/python3.10/site-packages/sqlalchemy/orm/session.py", line 2351, in execute
    return self._execute_internal(
  File "/home/dextermnesh/.local/share/virtualenvs/backend-GvKYjNis/lib/python3.10/site-packages/sqlalchemy/orm/session.py", line 2236, in _execute_internal
    result: Result[Any] = compile_state_cls.orm_execute_statement(
  File "/home/dextermnesh/.local/share/virtualenvs/backend-GvKYjNis/lib/python3.10/site-packages/sqlalchemy/orm/context.py", line 293, in orm_execute_statement
    result = conn.execute(
  File "/home/dextermnesh/.local/share/virtualenvs/backend-GvKYjNis/lib/python3.10/site-packages/sqlalchemy/engine/base.py", line 1418, in execute
    return meth(
  File "/home/dextermnesh/.local/share/virtualenvs/backend-GvKYjNis/lib/python3.10/site-packages/sqlalchemy/sql/elements.py", line 515, in _execute_on_connection
    return connection._execute_clauseelement(
  File "/home/dextermnesh/.local/share/virtualenvs/backend-GvKYjNis/lib/python3.10/site-packages/sqlalchemy/engine/base.py", line 1640, in _execute_clauseelement
    ret = self._execute_context(
  File "/home/dextermnesh/.local/share/virtualenvs/backend-GvKYjNis/lib/python3.10/site-packages/sqlalchemy/engine/base.py", line 1846, in _execute_context
    return self._exec_single_context(
  File "/home/dextermnesh/.local/share/virtualenvs/backend-GvKYjNis/lib/python3.10/site-packages/sqlalchemy/engine/base.py", line 1986, in _exec_single_context
    self._handle_dbapi_exception(
  File "/home/dextermnesh/.local/share/virtualenvs/backend-GvKYjNis/lib/python3.10/site-packages/sqlalchemy/engine/base.py", line 2353, in _handle_dbapi_exception
    raise sqlalchemy_exception.with_traceback(exc_info[2]) from e
  File "/home/dextermnesh/.local/share/virtualenvs/backend-GvKYjNis/lib/python3.10/site-packages/sqlalchemy/engine/base.py", line 1967, in _exec_single_context
    self.dialect.do_execute(
  File "/home/dextermnesh/.local/share/virtualenvs/backend-GvKYjNis/lib/python3.10/site-packages/sqlalchemy/engine/default.py", line 924, in do_execute
    cursor.execute(statement, parameters)
sqlalchemy.exc.ProgrammingError: (psycopg2.errors.UndefinedTable) relation "products" does not exist
LINE 2: FROM products
             ^

[SQL: SELECT products.id AS products_id, products.name AS products_name, products.description AS products_description, products.price AS products_price, products.stock_quantity AS products_stock_quantity, products.image_url AS products_image_url 
FROM products]
(Background on this error at: https://sqlalche.me/e/20/f405)
2024-07-17 16:36:32,541 ERROR: Exception on /products [GET] [in /home/dextermnesh/.local/share/virtualenvs/backend-GvKYjNis/lib/python3.10/site-packages/flask/app.py:838]
Traceback (most recent call last):
  File "/home/dextermnesh/.local/share/virtualenvs/backend-GvKYjNis/lib/python3.10/site-packages/sqlalchemy/engine/base.py", line 1967, in _exec_single_context
    self.dialect.do_execute(
  File "/home/dextermnesh/.local/share/virtualenvs/backend-GvKYjNis/lib/python3.10/site-packages/sqlalchemy/engine/default.py", line 924, in do_execute
    cursor.execute(statement, parameters)
psycopg2.errors.UndefinedTable: relation "products" does not exist
LINE 2: FROM products
             ^


The above exception was the direct cause of the following exception:

Traceback (most recent call last):
  File "/home/dextermnesh/.local/share/virtualenvs/backend-GvKYjNis/lib/python3.10/site-packages/flask/app.py", line 1473, in wsgi_app
    response = self.full_dispatch_request()
  File "/home/dextermnesh/.local/share/virtualenvs/backend-GvKYjNis/lib/python3.10/site-packages/flask/app.py", line 882, in full_dispatch_request
    rv = self.handle_user_exception(e)
  File "/home/dextermnesh/.local/share/virtualenvs/backend-GvKYjNis/lib/python3.10/site-packages/flask_cors/extension.py", line 178, in wrapped_function
    return cors_after_request(app.make_response(f(*args, **kwargs)))
  File "/home/dextermnesh/.local/share/virtualenvs/backend-GvKYjNis/lib/python3.10/site-packages/flask/app.py", line 880, in full_dispatch_request
    rv = self.dispatch_request()
  File "/home/dextermnesh/.local/share/virtualenvs/backend-GvKYjNis/lib/python3.10/site-packages/flask/app.py", line 865, in dispatch_request
    return self.ensure_sync(self.view_functions[rule.endpoint])(**view_args)  # type: ignore[no-any-return]
  File "/home/dextermnesh/Documents/testers/shopping-mall/backend/app.py", line 35, in get_products
    products = Product.query.all()
  File "/home/dextermnesh/.local/share/virtualenvs/backend-GvKYjNis/lib/python3.10/site-packages/sqlalchemy/orm/query.py", line 2673, in all
    return self._iter().all()  # type: ignore
  File "/home/dextermnesh/.local/share/virtualenvs/backend-GvKYjNis/lib/python3.10/site-packages/sqlalchemy/orm/query.py", line 2827, in _iter
    result: Union[ScalarResult[_T], Result[_T]] = self.session.execute(
  File "/home/dextermnesh/.local/share/virtualenvs/backend-GvKYjNis/lib/python3.10/site-packages/sqlalchemy/orm/session.py", line 2351, in execute
    return self._execute_internal(
  File "/home/dextermnesh/.local/share/virtualenvs/backend-GvKYjNis/lib/python3.10/site-packages/sqlalchemy/orm/session.py", line 2236, in _execute_internal
    result: Result[Any] = compile_state_cls.orm_execute_statement(
  File "/home/dextermnesh/.local/share/virtualenvs/backend-GvKYjNis/lib/python3.10/site-packages/sqlalchemy/orm/context.py", line 293, in orm_execute_statement
    result = conn.execute(
  File "/home/dextermnesh/.local/share/virtualenvs/backend-GvKYjNis/lib/python3.10/site-packages/sqlalchemy/engine/base.py", line 1418, in execute
    return meth(
  File "/home/dextermnesh/.local/share/virtualenvs/backend-GvKYjNis/lib/python3.10/site-packages/sqlalchemy/sql/elements.py", line 515, in _execute_on_connection
    return connection._execute_clauseelement(
  File "/home/dextermnesh/.local/share/virtualenvs/backend-GvKYjNis/lib/python3.10/site-packages/sqlalchemy/engine/base.py", line 1640, in _execute_clauseelement
    ret = self._execute_context(
  File "/home/dextermnesh/.local/share/virtualenvs/backend-GvKYjNis/lib/python3.10/site-packages/sqlalchemy/engine/base.py", line 1846, in _execute_context
    return self._exec_single_context(
  File "/home/dextermnesh/.local/share/virtualenvs/backend-GvKYjNis/lib/python3.10/site-packages/sqlalchemy/engine/base.py", line 1986, in _exec_single_context
    self._handle_dbapi_exception(
  File "/home/dextermnesh/.local/share/virtualenvs/backend-GvKYjNis/lib/python3.10/site-packages/sqlalchemy/engine/base.py", line 2353, in _handle_dbapi_exception
    raise sqlalchemy_exception.with_traceback(exc_info[2]) from e
  File "/home/dextermnesh/.local/share/virtualenvs/backend-GvKYjNis/lib/python3.10/site-packages/sqlalchemy/engine/base.py", line 1967, in _exec_single_context
    self.dialect.do_execute(
  File "/home/dextermnesh/.local/share/virtualenvs/backend-GvKYjNis/lib/python3.10/site-packages/sqlalchemy/engine/default.py", line 924, in do_execute
    cursor.execute(statement, parameters)
sqlalchemy.exc.ProgrammingError: (psycopg2.errors.UndefinedTable) relation "products" does not exist
LINE 2: FROM products
             ^

[SQL: SELECT products.id AS products_id, products.name AS products_name, products.description AS products_description, products.price AS products_price, products.stock_quantity AS products_stock_quantity, products.image_url AS products_image_url 
FROM products]
(Background on this error at: https://sqlalche.me/e/20/f405)
